<mujoco>
    <!--Sets up the main kinematic tree of the robot via nesting-->
    <body name="root" pos="0 0 0.040" euler="-1.5708 0 0">
        <geom name="root" type="mesh" class="visual" density="0" rgba="0.5 0.5 0.8 1" mesh="base_link"/>

        <!-- Left side -->
        <!--Back link-->
        <body name="robot0:Back_Link_L" pos="-0.053968 0.0175 0.0314992" quat="0.569709 0.569709 -0.418845 0.418845">
            <inertial pos="-0.000350268 0.0180111 -1.86653e-06" quat="0.999872 -8.5692e-05 -0.000105773 0.0159827" mass="0.00610621" diaginertia="9.37005e-07 8.15608e-07 4.73725e-07" />
            <joint name="robot0:Back_Joint_L" class="Jxm330H" axis="0 0 1" range="-1 1.84"/>
            <geom name="Back_Link_L" class="visual" rgba="1 0.6 0.15 1" mesh="Back_Link_L" />

            <!--Short link-->
            <body name="robot0:Short_Link_L" pos="0 0.037 0" quat="0.707107 0 0 0.707107">
                <inertial pos="0.020595 0.0025243 -7.7917e-08" quat="0.0333534 0.70632 -0.0333534 0.70632" mass="0.0034855" diaginertia="6.4109e-07 6.21195e-07 5.7554e-08" />
                <joint name="robot0:Short_Jonit_L" axis="0 0 1" range="-1.57 0.000" class="JS"/>
                <geom name="Short_Link_L" class="visual" rgba="1 0.6 0.15 1" mesh="Short_Link_L" />

                <!--Long (curved) link-->
                <body name="robot0:Long_Link_L" pos="0.0405 0 0" quat="0.49692 0 0 -0.867796">
                    <inertial pos="0.0735453 -0.00874881 5.23989e-10" quat="0.088758 0.701514 -0.088758 0.701514" mass="0.0133897" diaginertia="2.01078e-05 1.97593e-05 6.86317e-07" />
                    <joint name="robot0:Elbow_Joint_L" class="elbow" axis="0 0 1" range="-0.6 2"/>
                    <geom name="Long_Link_L" class="longlink" rgba="1 0.6 0.15 1" mesh="Long_Link_L" />

                    <!--End effector-->
                    <site name="Tip_L" pos="0.1135 -0.024 0" rgba="0 1 1 1" size="0.001" />
                    <body name="Hard_tip_L" pos="0.1135 -0.024 0">
                        <geom name="Hard_tip_L" class="Hard_tip" type="cylinder" size="0.008 0.010" rgba="0.125 0.785 0.785 0"/>
                    </body>

                </body>

            </body>

        </body>

        <!--Front link (connected to long link in shared-worked)-->
        <body name="robot0:Front_Link_L" pos="-0.0435284 0.0175 0.064906" quat="0.106677 0.699014 -0.699014 -0.106677">
            <inertial pos="1.64302e-06 0.021826 0.000500228" quat="0.49924 0.500664 -0.499738 0.500357" mass="0.00727755" diaginertia="1.3181e-06 8.8333e-07 8.29623e-07" />
            <joint name="robot0:Front_Joint_L" class="Jxm330F" type="hinge" axis="1 0 0" range="-1.85 0.85"/>
            <geom name="Front_Link_L" class="visual" rgba="1 0.6 0.15 1" mesh="Front_Link_L" />
        </body>

        <!-- Right side-->
        <!--Back link-->
        <body name="robot0:Back_Link_R" pos="0.053968 0.0175 0.0314992" quat="-0.418845 0.418845 0.569709 0.569709">
            <inertial pos="-0.00035027 0.018011 -1.8665e-06" quat="0.999872 -8.56915e-05 -0.000105773 0.0159825" mass="0.0061062" diaginertia="9.37004e-07 8.15606e-07 4.7372e-07" />
            <joint name="robot0:Back_Joint_R" class="Jxm330H" axis="0 0 -1" range="-1.84 1"/>
            <geom name="Back_Link_R" class="visual" rgba="1 0.6 0.15 1" mesh="Back_Link_R" />

            <!--Short link-->
            <body name="robot0:Short_Link_R" pos="0 0.037 0" quat="0.707107 0 0 0.707107">
                <inertial pos="0.020595 0.0025243 -7.7917e-08" quat="0.0333534 0.70632 -0.0333534 0.70632" mass="0.0034855" diaginertia="6.4109e-07 6.21195e-07 5.7554e-08" />
                <joint name="robot0:Short_Joint_R" axis="0 0 1" range="-1.57 0.000" class="JS"/>
                <geom name="Short_Link_R" class="visual" rgba="1 0.6 0.15 1" mesh="Short_Link_R" />

                <!--Long (curved) link-->
                <body name="robot0:Long_Link_R" pos="0.0405 0 0" quat="0.49692 0 0 -0.867796">
                    <inertial pos="0.0735453 -0.00874881 5.23989e-10" quat="0.088758 0.701514 -0.088758 0.701514" mass="0.0133897" diaginertia="2.01078e-05 1.97593e-05 6.86317e-07" />
                    <joint name="robot0:Elbow_Joint_R" class="elbow" axis="0 0 1" range="-0.6 2"/>
                    <geom name="Long_Link_R" class="longlink" rgba="1 0.6 0.15 1" mesh="Long_Link_R" />

                    <!--End effector-->
                    <site name="Tip_R" pos="0.1135 -0.024 0" rgba="0 1 1 1" size="0.001" />
                    <body name="Hard_tip_R" pos="0.1135 -0.024 0">
                        <geom name="Hard_tip_R" class="Hard_tip" size="0.008 0.010" rgba="0.125 0.785 0.785 0"/>
                    </body>

                </body>

            </body>

        </body>

        <!--Front link (connected to long link in shared-worked)-->
        <body name="robot0:Front_Link_R" pos="0.0435284 0.0175 0.064906" quat="0.106677 0.699014 0.699014 0.106677">
            <inertial pos="1.643e-06 0.021826 0.00050023" quat="0.49924 0.500664 -0.499738 0.500357" mass="0.0072776" diaginertia="1.3181e-06 8.8333e-07 8.29619e-07" />
            <joint name="robot0:Front_Joint_R" class="Jxm330F" type="hinge" axis="-1 0 0" range="-0.85 1.85"/>
            <geom name="Front_Link_R" class="visual" rgba="1 0.6 0.15 1" mesh="Front_Link_R" />
        </body>


    </body>

</mujoco>